Workbook

Sheet Start Here
B1: PR. Final Project - "Data Intelligence Dashboard"
B2: Built on your Final Project Dataset: 250 transactions, 50 customers, 10 products, 5 regions
B4: Required topic | C4: Where | D4: Status
B5: Date & Time: TODAY, NOW, DATEDIF, EOMONTH | C5: Analysis section 1, Raw Data O:P,R | D5: Done
B6: FILTER function | C6: Analysis section 2 | D6: Done (helper version + 365 formula)
B7: Conditional formatting with icons/arrows | C7: Analysis (MoM %), Dashboard | D7: Done
B8: Timestamp with NOW + iterative calc | C8: Analysis section 3 | D8: Done (iterative ON)
B9: What-if: Scenario Manager, Goal Seek | C9: Analysis section 4 | D9: Model ready - run the tools (Manual Steps)
B10: Linear regression (Toolpak) | C10: Analysis section 5 | D10: Formulas done - Toolpak run by hand
B11: Data analysis & storytelling | C11: Insights Report | D11: Done (live text)
B12: GroupBy / High-value customers | C12: Analysis section 6 | D12: Done
B13: Dashboard: pivots, pivot charts, slicers, timeline | C13: Dashboard + Manual Steps | D13: Interactive dropdown dashboard done; pivots/slicers by hand
B14: KPI indicators with conditional formatting | C14: Dashboard rows 7-13 | D14: Done
B15: Most purchased product / repeating names | C15: Analysis section 7 | D15: Done
... B18: Final report | C18: Insights Report | D18: Done
B20: Colour legend
B21: Yellow cell + blue text = input you can change
B22: Black text = formula (do not overwrite)
B23: Sheets: Raw Data > Analysis > Visualizations > Dashboard > Insights Report > Manual Steps
B24: Note: data runs 11-Apr-2024 to 11-Apr-2025, so Apr-2024 and Apr-2025 are partial months and are left out of the trend and KPIs.

Sheet Raw Data
A1: Transaction_ID | B1: Date | C1: Customer_ID | D1: Customer_Name | E1: Product_ID | F1: Product_Name | G1: Category | H1: Quantity | I1: Unit_Price | J1: Payment_Method | K1: Region | L1: Customer_Segment | M1: Customer_Since | N1: Total_Amount | O1: Month End | P1: Order Age (Months) | Q1: Filter Helper | R1: Tenure at Order (Months)
A2: TRX0155 | B2: 45393 | C2: CUST023 | D2: Paul Baker | E2: P009 | F2: Monitor | G2: Electronics | H2: 3 | I2: 249.99 | J2: Cash | K2: Central | L2: Basic | M2: 44425 | N2: 749.97 | O2: =EOMONTH(B2,0) -> 45412 | P2: =DATEDIF(B2,TODAY(),"m") -> 30 | Q2: =IF(K2=Analysis!$B$16,COUNTIF($K$2:K2,Analysis!$B$16),"") -> 1 | R2: =IFERROR(DATEDIF(M2,B2,"m"),"") -> 31
A3: TRX0023 | B3: 45396 | C3: CUST013 | D3: Joseph Jackson | E3: P009 | F3: Monitor | G3: Electronics | H3: 3 | I3: 249.99 | J3: Credit Card | K3: Central | L3: Premium | M3: 44575 | N3: 749.97 | O3: =EOMONTH(B3,0) -> 45412 | P3: =DATEDIF(B3,TODAY(),"m") -> 29 | Q3: =IF(K3=Analysis!$B$16,COUNTIF($K$2:K3,Analysis!$B$16),"") -> 2 | R3: =IFERROR(DATEDIF(M3,B3,"m"),"") -> 27
A4: TRX0139 | B4: 45399 | C4: CUST021 | D4: Kevin Scott | E4: P005 | F4: Blender | G4: Appliances | H4: 3 | I4: 59.99 | J4: PayPal | K4: South | L4: Standard | M4: 45262 | N4: 179.97 | O4: =EOMONTH(B4,0) -> 45412 | P4: =DATEDIF(B4,TODAY(),"m") -> 29 | Q4: =IF(K4=Analysis!$B$16,COUNTIF($K$2:K4,Analysis!$B$16),"") | R4: =IFERROR(DATEDIF(M4,B4,"m"),"") -> 4
A5: TRX0043 | B5: 45400 | C5: CUST046 | D5: Kathleen Bennett | E5: P005 | F5: Blender | G5: Appliances | H5: 3 | I5: 59.99 | J5: Cash | K5: North | L5: Premium | M5: 45114 | N5: 179.97 | O5: =EOMONTH(B5,0) -> 45412 | P5: =DATEDIF(B5,TODAY(),"m") -> 29 | Q5: =IF(K5=Analysis!$B$16,COUNTIF($K$2:K5,Analysis!$B$16),"") | R5: =IFERROR(DATEDIF(M5,B5,"m"),"") -> 9
A6: TRX0212 | B6: 45400 | C6: CUST003 | D6: Michael Brown | E6: P008 | F6: Bookshelf | G6: Furniture | H6: 5 | I6: 149.99 | J6: Credit Card | K6: North | L6: Premium | M6: 45295 | N6: 749.95 | O6: =EOMONTH(B6,0) -> 45412 | P6: =DATEDIF(B6,TODAY(),"m") -> 29 | Q6: =IF(K6=Analysis!$B$16,COUNTIF($K$2:K6,Analysis!$B$16),"") | R6: =IFERROR(DATEDIF(M6,B6,"m"),"") -> 3
A7: TRX0092 | B7: 45403 | C7: CUST024 | D7: Dorothy Nelson | E7: P005 | F7: Blender | G7: Appliances | H7: 2 | I7: 59.99 | J7: Cash | K7: West | L7: Standard | M7: 44746 | N7: 119.98 | O7: =EOMONTH(B7,0) -> 45412 | P7: =DATEDIF(B7,TODAY(),"m") -> 29 | Q7: =IF(K7=Analysis!$B$16,COUNTIF($K$2:K7,Analysis!$B$16),"") | R7: =IFERROR(DATEDIF(M7,B7,"m"),"") -> 21
A8: TRX0193 | B8: 45403 | C8: CUST024 | D8: Dorothy Nelson | E8: P003 | F8: Headphones | G8: Electronics | H8: 5 | I8: 149.99 | J8: Credit Card | K8: Central | L8: Standard | M8: 44418 | N8: 749.95 | O8: =EOMONTH(B8,0) -> 45412 | P8: =DATEDIF(B8,TODAY(),"m") -> 29 | Q8: =IF(K8=Analysis!$B$16,COUNTIF($K$2:K8,Analysis!$B$16),"") -> 3 | R8: =IFERROR(DATEDIF(M8,B8,"m"),"") -> 32
A9: TRX0240 | B9: 45403 | C9: CUST017 | D9: Charles Allen | E9: P005 | F9: Blender | G9: Appliances | H9: 3 | I9: 59.99 | J9: Debit Card | K9: South | L9: Basic | M9: 45007 | N9: 179.97 | O9: =EOMONTH(B9,0) -> 45412 | P9: =DATEDIF(B9,TODAY(),"m") -> 29 | Q9: =IF(K9=Analysis!$B$16,COUNTIF($K$2:K9,Analysis!$B$16),"") | R9: =IFERROR(DATEDIF(M9,B9,"m"),"") -> 12
A10: TRX0135 | B10: 45405 | C10: CUST009 | D10: Robert Thomas | E10: P001 | F10: Laptop | G10: Electronics | H10: 3 | I10: 899.99 | J10: PayPal | K10: East | L10: Standard | M10: 45299 | N10: 2699.97 | O10: =EOMONTH(B10,0) -> 45412 | P10: =DATEDIF(B10,TODAY(),"m") -> 29 | Q10: =IF(K10=Analysis!$B$16,COUNTIF($K$2:K10,Analysis!$B$16),"") | R10: =IFERROR(DATEDIF(M10,B10,"m"),"") -> 3
A11: TRX0138 | B11: 45408 | C11: CUST022 | D11: Susan Green | E11: P008 | F11: Bookshelf | G11: Furniture | H11: 1 | I11: 149.99 | J11: Credit Card | K11: West | L11: Standard | M11: 45103 | N11: 149.99 | O11: =EOMONTH(B11,0) -> 45412 | P11: =DATEDIF(B11,TODAY(),"m") -> 29 | Q11: =IF(K11=Analysis!$B$16,COUNTIF($K$2:K11,Analysis!$B$16),"") | R11: =IFERROR(DATEDIF(M11,B11,"m"),"") -> 10
A12: TRX0185 | B12: 45408 | C12: CUST026 | D12: Karen Hill | E12: P005 | F12: Blender | G12: Appliances | H12: 3 | I12: 59.99 | J12: Cash | K12: West | L12: Premium | M12: 45207 | N12: 179.97 | O12: =EOMONTH(B12,0) -> 45412 | P12: =DATEDIF(B12,TODAY(),"m") -> 29 | Q12: =IF(K12=Analysis!$B$16,COUNTIF($K$2:K12,Analysis!$B$16),"") | R12: =IFERROR(DATEDIF(M12,B12,"m"),"") -> 6
A13: TRX0209 | B13: 45408 | C13: CUST046 | D13: Kathleen Bennett | E13: P008 | F13: Bookshelf | G13: Furniture | H13: 5 | I13: 149.99 | J13: Debit Card | K13: North | L13: Basic | M13: 44830 | N13: 749.95 | O13: =EOMONTH(B13,0) -> 45412 | P13: =DATEDIF(B13,TODAY(),"m") -> 29 | Q13: =IF(K13=Analysis!$B$16,COUNTIF($K$2:K13,Analysis!$B$16),"") | R13: =IFERROR(DATEDIF(M13,B13,"m"),"") -> 19
... A251: TRX0120 | B251: 45758 | C251: CUST045 | D251: Douglas Watson | E251: P002 | F251: Smartphone | G251: Electronics | H251: 3 | I251: 699.99 | J251: PayPal | K251: North | L251: Basic | M251: 44909 | N251: 2099.97 | O251: =EOMONTH(B251,0) -> 45777 | P251: =DATEDIF(B251,TODAY(),"m") -> 18 | Q251: =IF(K251=Analysis!$B$16,COUNTIF($K$2:K251,Analysis!$B$16),"") | R251: =IFERROR(DATEDIF(M251,B251,"m"),"") -> 27

Sheet Analysis
A1: ANALYSIS - every number is a formula (yellow cells with blue text are inputs you can change)
A3: 1. DATE & TIME FUNCTIONS (TODAY, NOW, DATEDIF, EOMONTH)
A4: Today's date [TODAY] | B4: =TODAY() -> 46307
A5: Current date & time [NOW] | B5: =NOW() -> 46307.275
A6: First order date | B6: =MIN('Raw Data'!$B$2:$B$251) -> 45393
A7: Latest order date | B7: =MAX('Raw Data'!$B$2:$B$251) -> 45758
A8: Days since last order | B8: =TODAY()-B7 -> 549
A9: Data span [DATEDIF] | B9: =DATEDIF(B6,B7,"y")&" yr "&DATEDIF(B6,B7,"ym")&" months "&DATEDIF(B6,B7,"md")&" days" -> 1 yr 0 months 0 days
A10: Month-end of latest order [EOMONTH] | B10: =EOMONTH(B7,0) -> 45777
A11: Days left in that month | B11: =B10-B7 -> 19
A12: First day of next month | B12: =EOMONTH(B7,0)+1 -> 45778
A13: Months from first order till today | B13: =DATEDIF(B6,TODAY(),"m") -> 30
A15: 2. FILTER FUNCTION - multi-value return (pick a region)
A16: Select Region | B16: Central
A17: Excel 365 FILTER formula to type: | B17: =FILTER('Raw Data'!A2:N251,'Raw Data'!K2:K251=B16,"No data")
A18: Matching orders | B18: =COUNTIF('Raw Data'!$K$2:$K$251,B16) -> 54
A20: # | B20: Transaction | C20: Date | D20: Customer | E20: Product | F20: Total Amount
A21: 1 | B21: =IFERROR(INDEX('Raw Data'!$A$2:$A$251,MATCH($A21,'Raw Data'!$Q$2:$Q$251,0)),"") -> TRX0155 | C21: =IFERROR(INDEX('Raw Data'!$B$2:$B$251,MATCH($A21,'Raw Data'!$Q$2:$Q$251,0)),"") -> 45393 | D21: =IFERROR(INDEX('Raw Data'!$D$2:$D$251,MATCH($A21,'Raw Data'!$Q$2:$Q$251,0)),"") -> Paul Baker | E21: =IFERROR(INDEX('Raw Data'!$F$2:$F$251,MATCH($A21,'Raw Data'!$Q$2:$Q$251,0)),"") -> Monitor | F21: =IFERROR(INDEX('Raw Data'!$N$2:$N$251,MATCH($A21,'Raw Data'!$Q$2:$Q$251,0)),"") -> 749.97
A22: 2 | B22: =IFERROR(INDEX('Raw Data'!$A$2:$A$251,MATCH($A22,'Raw Data'!$Q$2:$Q$251,0)),"") -> TRX0023 | C22: =IFERROR(INDEX('Raw Data'!$B$2:$B$251,MATCH($A22,'Raw Data'!$Q$2:$Q$251,0)),"") -> 45396 | D22: =IFERROR(INDEX('Raw Data'!$D$2:$D$251,MATCH($A22,'Raw Data'!$Q$2:$Q$251,0)),"") -> Joseph Jackson | E22: =IFERROR(INDEX('Raw Data'!$F$2:$F$251,MATCH($A22,'Raw Data'!$Q$2:$Q$251,0)),"") -> Monitor | F22: =IFERROR(INDEX('Raw Data'!$N$2:$N$251,MATCH($A22,'Raw Data'!$Q$2:$Q$251,0)),"") -> 749.97
A23: 3 | B23: =IFERROR(INDEX('Raw Data'!$A$2:$A$251,MATCH($A23,'Raw Data'!$Q$2:$Q$251,0)),"") -> TRX0193 | C23: =IFERROR(INDEX('Raw Data'!$B$2:$B$251,MATCH($A23,'Raw Data'!$Q$2:$Q$251,0)),"") -> 45403 | D23: =IFERROR(INDEX('Raw Data'!$D$2:$D$251,MATCH($A23,'Raw Data'!$Q$2:$Q$251,0)),"") -> Dorothy Nelson | E23: =IFERROR(INDEX('Raw Data'!$F$2:$F$251,MATCH($A23,'Raw Data'!$Q$2:$Q$251,0)),"") -> Headphones | F23: =IFERROR(INDEX('Raw Data'!$N$2:$N$251,MATCH($A23,'Raw Data'!$Q$2:$Q$251,0)),"") -> 749.95
A24: 4 | B24: =IFERROR(INDEX('Raw Data'!$A$2:$A$251,MATCH($A24,'Raw Data'!$Q$2:$Q$251,0)),"") -> TRX0063 | C24: =IFERROR(INDEX('Raw Data'!$B$2:$B$251,MATCH($A24,'Raw Data'!$Q$2:$Q$251,0)),"") -> 45425 | D24: =IFERROR(INDEX('Raw Data'!$D$2:$D$251,MATCH($A24,'Raw Data'!$Q$2:$Q$251,0)),"") -> Helen Roberts | E24: =IFERROR(INDEX('Raw Data'!$F$2:$F$251,MATCH($A24,'Raw Data'!$Q$2:$Q$251,0)),"") -> Blender | F24: =IFERROR(INDEX('Raw Data'!$N$2:$N$251,MATCH($A24,'Raw Data'!$Q$2:$Q$251,0)),"") -> 119.98
A25: 5 | B25: =IFERROR(INDEX('Raw Data'!$A$2:$A$251,MATCH($A25,'Raw Data'!$Q$2:$Q$251,0)),"") -> TRX0202 | C25: =IFERROR(INDEX('Raw Data'!$B$2:$B$251,MATCH($A25,'Raw Data'!$Q$2:$Q$251,0)),"") -> 45441 | D25: =IFERROR(INDEX('Raw Data'!$D$2:$D$251,MATCH($A25,'Raw Data'!$Q$2:$Q$251,0)),"") -> Harry Morgan | E25: =IFERROR(INDEX('Raw Data'!$F$2:$F$251,MATCH($A25,'Raw Data'!$Q$2:$Q$251,0)),"") -> Keyboard | F25: =IFERROR(INDEX('Raw Data'!$N$2:$N$251,MATCH($A25,'Raw Data'!$Q$2:$Q$251,0)),"") -> 269.97
A26: 6 | B26: =IFERROR(INDEX('Raw Data'!$A$2:$A$251,MATCH($A26,'Raw Data'!$Q$2:$Q$251,0)),"") -> TRX0088 | C26: =IFERROR(INDEX('Raw Data'!$B$2:$B$251,MATCH($A26,'Raw Data'!$Q$2:$Q$251,0)),"") -> 45456 | D26: =IFERROR(INDEX('Raw Data'!$D$2:$D$251,MATCH($A26,'Raw Data'!$Q$2:$Q$251,0)),"") -> Lisa Anderson | E26: =IFERROR(INDEX('Raw Data'!$F$2:$F$251,MATCH($A26,'Raw Data'!$Q$2:$Q$251,0)),"") -> Keyboard | F26: =IFERROR(INDEX('Raw Data'!$N$2:$N$251,MATCH($A26,'Raw Data'!$Q$2:$Q$251,0)),"") -> 449.95
A27: 7 | B27: =IFERROR(INDEX('Raw Data'!$A$2:$A$251,MATCH($A27,'Raw Data'!$Q$2:$Q$251,0)),"") -> TRX0078 | C27: =IFERROR(INDEX('Raw Data'!$B$2:$B$251,MATCH($A27,'Raw Data'!$Q$2:$Q$251,0)),"") -> 45469 | D27: =IFERROR(INDEX('Raw Data'!$D$2:$D$251,MATCH($A27,'Raw Data'!$Q$2:$Q$251,0)),"") -> Kevin Scott | E27: =IFERROR(INDEX('Raw Data'!$F$2:$F$251,MATCH($A27,'Raw Data'!$Q$2:$Q$251,0)),"") -> Coffee Maker | F27: =IFERROR(INDEX('Raw Data'!$N$2:$N$251,MATCH($A27,'Raw Data'!$Q$2:$Q$251,0)),"") -> 79.99
A28: 8 | B28: =IFERROR(INDEX('Raw Data'!$A$2:$A$251,MATCH($A28,'Raw Data'!$Q$2:$Q$251,0)),"") -> TRX0096 | C28: =IFERROR(INDEX('Raw Data'!$B$2:$B$251,MATCH($A28,'Raw Data'!$Q$2:$Q$251,0)),"") -> 45474 | D28: =IFERROR(INDEX('Raw Data'!$D$2:$D$251,MATCH($A28,'Raw Data'!$Q$2:$Q$251,0)),"") -> Emma Wilson | E28: =IFERROR(INDEX('Raw Data'!$F$2:$F$251,MATCH($A28,'Raw Data'!$Q$2:$Q$251,0)),"") -> Keyboard | F28: =IFERROR(INDEX('Raw Data'!$N$2:$N$251,MATCH($A28,'Raw Data'!$Q$2:$Q$251,0)),"") -> 179.98
A29: 9 | B29: =IFERROR(INDEX('Raw Data'!$A$2:$A$251,MATCH($A29,'Raw Data'!$Q$2:$Q$251,0)),"") -> TRX0070 | C29: =IFERROR(INDEX('Raw Data'!$B$2:$B$251,MATCH($A29,'Raw Data'!$Q$2:$Q$251,0)),"") -> 45476 | D29: =IFERROR(INDEX('Raw Data'!$D$2:$D$251,MATCH($A29,'Raw Data'!$Q$2:$Q$251,0)),"") -> David Martinez | E29: =IFERROR(INDEX('Raw Data'!$F$2:$F$251,MATCH($A29,'Raw Data'!$Q$2:$Q$251,0)),"") -> Coffee Maker | F29: =IFERROR(INDEX('Raw Data'!$N$2:$N$251,MATCH($A29,'Raw Data'!$Q$2:$Q$251,0)),"") -> 399.95
A30: 10 | B30: =IFERROR(INDEX('Raw Data'!$A$2:$A$251,MATCH($A30,'Raw Data'!$Q$2:$Q$251,0)),"") -> TRX0018 | C30: =IFERROR(INDEX('Raw Data'!$B$2:$B$251,MATCH($A30,'Raw Data'!$Q$2:$Q$251,0)),"") -> 45484 | D30: =IFERROR(INDEX('Raw Data'!$D$2:$D$251,MATCH($A30,'Raw Data'!$Q$2:$Q$251,0)),"") -> Joseph Jackson | E30: =IFERROR(INDEX('Raw Data'!$F$2:$F$251,MATCH($A30,'Raw Data'!$Q$2:$Q$251,0)),"") -> Headphones | F30: =IFERROR(INDEX('Raw Data'!$N$2:$N$251,MATCH($A30,'Raw Data'!$Q$2:$Q$251,0)),"") -> 149.99
A31: Shows the first 10 matches using a helper column (works in every Excel version). In Excel 365 the FILTER formula above returns all matches in one cell.
A33: 3. TIMESTAMP using NOW() + iterative calculation
A34: Type anything here ->
A35: Timestamp (freezes once typed) | B35: =IF(B34="","",IF(B35="",NOW(),B35))
A36: Needs File > Options > Formulas > Enable iterative calculation (already ON in this file).
A38: 4. WHAT-IF ANALYSIS (Scenario Manager + Goal Seek)
A39: Base revenue (actual) | B39: =SUM('Raw Data'!$N$2:$N$251) -> 229192.47
A40: Price change % | B40: 0.05
A41: Quantity change % | B41: 0.1
A42: Discount % | B42: 0.02
A43: Projected revenue | B43: =B39*(1+B40)*(1+B41)*(1-B42) -> 259422.96
A44: Change vs base | B44: =B43-B39 -> 30230.487
A45: Goal Seek target revenue | B45: 290000 | C45: My assumption: 25% above actual revenue - change it
...

Sheet Visualizations
A1: VISUALIZATIONS - charts built from the Analysis sheet

Sheet Dashboard
B1: DATA INTELLIGENCE DASHBOARD
B2: ="Customer transactions | Data: "&TEXT(Analysis!B6,"dd mmm yyyy")&" to "&TEXT(Analysis!B7,"dd mmm yyyy")&" | Opened "&TEXT(NOW(),"dd mmm yyyy hh:mm") -> Customer transactions | Data: 11 Apr 2024 to 11 Apr 2025 | Opened 12 Oct 2026 06:35
B4: REGION | C4: All | F4: CATEGORY | G4: All | J4: PAYMENT | K4: All
B5: Pick a value from the yellow dropdowns - every card and chart below updates. Choose All to reset.
B7: TOTAL REVENUE | E7: ORDERS | H7: UNITS SOLD | K7: AVG ORDER VALUE
B8: ='Dash Data'!B8 -> 229192.47 | E8: ='Dash Data'!B9 -> 250 | H8: ='Dash Data'!B10 -> 753 | K8: ='Dash Data'!B11 -> 916.76988
B9: =TEXT('Dash Data'!B12,"0.0%")&" of all revenue" -> 100.0% of all revenue | E9: ="Avg order "&TEXT('Dash Data'!B11,"$#,##0") -> Avg order $917 | H9: =IFERROR(TEXT('Dash Data'!B10/'Dash Data'!B9,"0.0"),"0")&" units per order" -> 3.0 units per order | K9: =IFERROR(TEXT('Dash Data'!B11/'Dash Data'!B13-1,"+0%;-0%")&" vs overall","-") -> +0% vs overall
B11: MONTH-ON-MONTH GROWTH | E11: LAST MONTH vs AVERAGE | H11: TOP PRODUCT | K11: TOP CUSTOMER
B12: ='Dash Data'!B16 -> 0.23834149 | E12: ='Dash Data'!B18 -> 1.087434 | H12: ='Dash Data'!B19 -> Laptop | K12: ='Dash Data'!B21 -> Mark Carter
B13: ='Dash Data'!B38&" vs "&'Dash Data'!B37 -> Mar-25 vs Feb-25 | E13: ="Avg month "&TEXT('Dash Data'!B17,"$#,##0") -> Avg month $18,299 | H13: =TEXT('Dash Data'!B20,"$#,##0")&" revenue" -> $67,499 revenue | K13: =TEXT('Dash Data'!B22,"$#,##0")&" revenue" -> $15,660 revenue
B15: =IF('Dash Data'!B9=0,"No transactions match this selection - change a filter.","Showing "&IF(C4="All","all regions",C4&" region")&", "&IF(G4="All","all categories",G4)&", "&IF(K4="All","all payment methods",K4&" payments")&": "&TEXT('Dash Data'!B8,"$#,##0")&" revenue from "&'Dash Data'!B9&" orders. Best month: "&'Dash Data'!B23&".") -> Showing all regions, all categories, all payment methods: $229,192 revenue from 250 orders. Best month: Jan-25.
B65: Note: Apr-2024 and Apr-2025 are partial months (data runs 11-Apr-2024 to 11-Apr-2025), so monthly figures use full months May-2024 to Mar-2025.

Sheet Dash Data
A1: DASHBOARD ENGINE - do not edit. It reads the dropdowns on the Dashboard sheet.
A3: Region criteria | B3: =IF(Dashboard!C4="All","*",Dashboard!C4) -> *
A4: Category criteria | B4: =IF(Dashboard!G4="All","*",Dashboard!G4) -> *
A5: Payment criteria | B5: =IF(Dashboard!K4="All","*",Dashboard!K4) -> *
A8: Revenue (selection) | B8: =SUMIFS('Raw Data'!$N$2:$N$251,'Raw Data'!$K$2:$K$251,$B$3,'Raw Data'!$G$2:$G$251,$B$4,'Raw Data'!$J$2:$J$251,$B$5) -> 229192.47
A9: Orders | B9: =COUNTIFS('Raw Data'!$K$2:$K$251,$B$3,'Raw Data'!$G$2:$G$251,$B$4,'Raw Data'!$J$2:$J$251,$B$5) -> 250
A10: Units sold | B10: =SUMIFS('Raw Data'!$H$2:$H$251,'Raw Data'!$K$2:$K$251,$B$3,'Raw Data'!$G$2:$G$251,$B$4,'Raw Data'!$J$2:$J$251,$B$5) -> 753
A11: Average order value | B11: =IFERROR(B8/B9,0) -> 916.76988
A12: Share of all revenue | B12: =B8/Analysis!B39 -> 1
A13: Overall avg order value | B13: =Analysis!E180 -> 916.76988
A14: Last full month revenue | B14: =C38 -> 19899.38
A15: Previous month revenue | B15: =C37 -> 16069.38
A16: Month-on-month growth | B16: =IFERROR(B14/B15-1,0) -> 0.23834149
A17: Average full month | B17: =AVERAGE(C28:C38) -> 18299.392
A18: Last month vs average | B18: =IFERROR(B14/B17,0) -> 1.087434
A19: Top product | B19: =IF(H43=0,"-",G43) -> Laptop
A20: Top product revenue | B20: =H43 -> 67499.25
A21: Top customer | B21: =IF(H82=0,"-",G82) -> Mark Carter
A22: Top customer revenue | B22: =H82 -> 15659.65
A23: Best month | B23: =IF(B8=0,"-",INDEX(B28:B38,MATCH(MAX(C28:C38),C28:C38,0))) -> Jan-25
A27: Month Start | B27: Label | C27: Revenue | D27: MoM %
A28: 45413 | B28: =TEXT(A28,"mmm-yy") -> May-24 | C28: =SUMIFS('Raw Data'!$N$2:$N$251,'Raw Data'!$B$2:$B$251,">="&A28,'Raw Data'!$B$2:$B$251,"<="&EOMONTH(A28,0),'Raw Data'!$K$2:$K$251,$B$3,'Raw Data'!$G$2:$G$251,$B$4,'Raw Data'!$J$2:$J$251,$B$5) -> 17039.35
A29: 45444 | B29: =TEXT(A29,"mmm-yy") -> Jun-24 | C29: =SUMIFS('Raw Data'!$N$2:$N$251,'Raw Data'!$B$2:$B$251,">="&A29,'Raw Data'!$B$2:$B$251,"<="&EOMONTH(A29,0),'Raw Data'!$K$2:$K$251,$B$3,'Raw Data'!$G$2:$G$251,$B$4,'Raw Data'!$J$2:$J$251,$B$5) -> 19299.45 | D29: =IFERROR(C29/C28-1,0) -> 0.13264004
A30: 45474 | B30: =TEXT(A30,"mmm-yy") -> Jul-24 | C30: =SUMIFS('Raw Data'!$N$2:$N$251,'Raw Data'!$B$2:$B$251,">="&A30,'Raw Data'!$B$2:$B$251,"<="&EOMONTH(A30,0),'Raw Data'!$K$2:$K$251,$B$3,'Raw Data'!$G$2:$G$251,$B$4,'Raw Data'!$J$2:$J$251,$B$5) -> 18479.4 | D30: =IFERROR(C30/C29-1,0) -> -0.042490848
A31: 45505 | B31: =TEXT(A31,"mmm-yy") -> Aug-24 | C31: =SUMIFS('Raw Data'!$N$2:$N$251,'Raw Data'!$B$2:$B$251,">="&A31,'Raw Data'!$B$2:$B$251,"<="&EOMONTH(A31,0),'Raw Data'!$K$2:$K$251,$B$3,'Raw Data'!$G$2:$G$251,$B$4,'Raw Data'!$J$2:$J$251,$B$5) -> 15759.43 | D31: =IFERROR(C31/C30-1,0) -> -0.1471893
A32: 45536 | B32: =TEXT(A32,"mmm-yy") -> Sep-24 | C32: =SUMIFS('Raw Data'!$N$2:$N$251,'Raw Data'!$B$2:$B$251,">="&A32,'Raw Data'!$B$2:$B$251,"<="&EOMONTH(A32,0),'Raw Data'!$K$2:$K$251,$B$3,'Raw Data'!$G$2:$G$251,$B$4,'Raw Data'!$J$2:$J$251,$B$5) -> 12989.51 | D32: =IFERROR(C32/C31-1,0) -> -0.1757627
A33: 45566 | B33: =TEXT(A33,"mmm-yy") -> Oct-24 | C33: =SUMIFS('Raw Data'!$N$2:$N$251,'Raw Data'!$B$2:$B$251,">="&A33,'Raw Data'!$B$2:$B$251,"<="&EOMONTH(A33,0),'Raw Data'!$K$2:$K$251,$B$3,'Raw Data'!$G$2:$G$251,$B$4,'Raw Data'!$J$2:$J$251,$B$5) -> 20609.52 | D33: =IFERROR(C33/C32-1,0) -> 0.58662798
A34: 45597 | B34: =TEXT(A34,"mmm-yy") -> Nov-24 | C34: =SUMIFS('Raw Data'!$N$2:$N$251,'Raw Data'!$B$2:$B$251,">="&A34,'Raw Data'!$B$2:$B$251,"<="&EOMONTH(A34,0),'Raw Data'!$K$2:$K$251,$B$3,'Raw Data'!$G$2:$G$251,$B$4,'Raw Data'!$J$2:$J$251,$B$5) -> 12309.44 | D34: =IFERROR(C34/C33-1,0) -> -0.40273039
A35: 45627 | B35: =TEXT(A35,"mmm-yy") -> Dec-24 | C35: =SUMIFS('Raw Data'!$N$2:$N$251,'Raw Data'!$B$2:$B$251,">="&A35,'Raw Data'!$B$2:$B$251,"<="&EOMONTH(A35,0),'Raw Data'!$K$2:$K$251,$B$3,'Raw Data'!$G$2:$G$251,$B$4,'Raw Data'!$J$2:$J$251,$B$5) -> 23039.3 | D35: =IFERROR(C35/C34-1,0) -> 0.87167735
A36: 45658 | B36: =TEXT(A36,"mmm-yy") -> Jan-25 | C36: =SUMIFS('Raw Data'!$N$2:$N$251,'Raw Data'!$B$2:$B$251,">="&A36,'Raw Data'!$B$2:$B$251,"<="&EOMONTH(A36,0),'Raw Data'!$K$2:$K$251,$B$3,'Raw Data'!$G$2:$G$251,$B$4,'Raw Data'!$J$2:$J$251,$B$5) -> 25799.15 | D36: =IFERROR(C36/C35-1,0) -> 0.1197888
A37: 45689 | B37: =TEXT(A37,"mmm-yy") -> Feb-25 | C37: =SUMIFS('Raw Data'!$N$2:$N$251,'Raw Data'!$B$2:$B$251,">="&A37,'Raw Data'!$B$2:$B$251,"<="&EOMONTH(A37,0),'Raw Data'!$K$2:$K$251,$B$3,'Raw Data'!$G$2:$G$251,$B$4,'Raw Data'!$J$2:$J$251,$B$5) -> 16069.38 | D37: =IFERROR(C37/C36-1,0) -> -0.37713529
A38: 45717 | B38: =TEXT(A38,"mmm-yy") -> Mar-25 | C38: =SUMIFS('Raw Data'!$N$2:$N$251,'Raw Data'!$B$2:$B$251,">="&A38,'Raw Data'!$B$2:$B$251,"<="&EOMONTH(A38,0),'Raw Data'!$K$2:$K$251,$B$3,'Raw Data'!$G$2:$G$251,$B$4,'Raw Data'!$J$2:$J$251,$B$5) -> 19899.38 | D38: =IFERROR(C38/C37-1,0) -> 0.23834149
A42: Product | B42: Revenue | C42: Units | D42: Rank | F42: Rank | G42: Product (sorted) | H42: Revenue
A43: Blender | B43: =SUMIFS('Raw Data'!$N$2:$N$251,'Raw Data'!$F$2:$F$251,A43,'Raw Data'!$K$2:$K$251,$B$3,'Raw Data'!$G$2:$G$251,$B$4,'Raw Data'!$J$2:$J$251,$B$5) -> 5219.13 | C43: =SUMIFS('Raw Data'!$H$2:$H$251,'Raw Data'!$F$2:$F$251,A43,'Raw Data'!$K$2:$K$251,$B$3,'Raw Data'!$G$2:$G$251,$B$4,'Raw Data'!$J$2:$J$251,$B$5) -> 87 | D43: =RANK(B43,$B$43:$B$52)+COUNTIF($B$43:B43,B43)-1 -> 9 | F43: 1 | G43: =INDEX($A$43:$A$52,MATCH(F43,$D$43:$D$52,0)) -> Laptop | H43: =INDEX($B$43:$B$52,MATCH(F43,$D$43:$D$52,0)) -> 67499.25
A44: Bookshelf | B44: =SUMIFS('Raw Data'!$N$2:$N$251,'Raw Data'!$F$2:$F$251,A44,'Raw Data'!$K$2:$K$251,$B$3,'Raw Data'!$G$2:$G$251,$B$4,'Raw Data'!$J$2:$J$251,$B$5) -> 15298.98 | C44: =SUMIFS('Raw Data'!$H$2:$H$251,'Raw Data'!$F$2:$F$251,A44,'Raw Data'!$K$2:$K$251,$B$3,'Raw Data'!$G$2:$G$251,$B$4,'Raw Data'!$J$2:$J$251,$B$5) -> 102 | D44: =RANK(B44,$B$43:$B$52)+COUNTIF($B$43:B44,B44)-1 -> 5 | F44: 2 | G44: =INDEX($A$43:$A$52,MATCH(F44,$D$43:$D$52,0)) -> Smartphone | H44: =INDEX($B$43:$B$52,MATCH(F44,$D$43:$D$52,0)) -> 67199.04
A45: Coffee Maker | B45: =SUMIFS('Raw Data'!$N$2:$N$251,'Raw Data'!$F$2:$F$251,A45,'Raw Data'!$K$2:$K$251,$B$3,'Raw Data'!$G$2:$G$251,$B$4,'Raw Data'!$J$2:$J$251,$B$5) -> 3119.61 | C45: =SUMIFS('Raw Data'!$H$2:$H$251,'Raw Data'!$F$2:$F$251,A45,'Raw Data'!$K$2:$K$251,$B$3,'Raw Data'!$G$2:$G$251,$B$4,'Raw Data'!$J$2:$J$251,$B$5) -> 39 | D45: =RANK(B45,$B$43:$B$52)+COUNTIF($B$43:B45,B45)-1 -> 10 | F45: 3 | G45: =INDEX($A$43:$A$52,MATCH(F45,$D$43:$D$52,0)) -> Desk | H45: =INDEX($B$43:$B$52,MATCH(F45,$D$43:$D$52,0)) -> 23399.22
A46: Desk | B46: =SUMIFS('Raw Data'!$N$2:$N$251,'Raw Data'!$F$2:$F$251,A46,'Raw Data'!$K$2:$K$251,$B$3,'Raw Data'!$G$2:$G$251,$B$4,'Raw Data'!$J$2:$J$251,$B$5) -> 23399.22 | C46: =SUMIFS('Raw Data'!$H$2:$H$251,'Raw Data'!$F$2:$F$251,A46,'Raw Data'!$K$2:$K$251,$B$3,'Raw Data'!$G$2:$G$251,$B$4,'Raw Data'!$J$2:$J$251,$B$5) -> 78 | D46: =RANK(B46,$B$43:$B$52)+COUNTIF($B$43:B46,B46)-1 -> 3 | F46: 4 | G46: =INDEX($A$43:$A$52,MATCH(F46,$D$43:$D$52,0)) -> Monitor | H46: =INDEX($B$43:$B$52,MATCH(F46,$D$43:$D$52,0)) -> 21999.12
A47: Headphones | B47: =SUMIFS('Raw Data'!$N$2:$N$251,'Raw Data'!$F$2:$F$251,A47,'Raw Data'!$K$2:$K$251,$B$3,'Raw Data'!$G$2:$G$251,$B$4,'Raw Data'!$J$2:$J$251,$B$5) -> 7049.53 | C47: =SUMIFS('Raw Data'!$H$2:$H$251,'Raw Data'!$F$2:$F$251,A47,'Raw Data'!$K$2:$K$251,$B$3,'Raw Data'!$G$2:$G$251,$B$4,'Raw Data'!$J$2:$J$251,$B$5) -> 47 | D47: =RANK(B47,$B$43:$B$52)+COUNTIF($B$43:B47,B47)-1 -> 8 | F47: 5 | G47: =INDEX($A$43:$A$52,MATCH(F47,$D$43:$D$52,0)) -> Bookshelf | H47: =INDEX($B$43:$B$52,MATCH(F47,$D$43:$D$52,0)) -> 15298.98
A48: Keyboard | B48: =SUMIFS('Raw Data'!$N$2:$N$251,'Raw Data'!$F$2:$F$251,A48,'Raw Data'!$K$2:$K$251,$B$3,'Raw Data'!$G$2:$G$251,$B$4,'Raw Data'!$J$2:$J$251,$B$5) -> 8009.11 | C48: =SUMIFS('Raw Data'!$H$2:$H$251,'Raw Data'!$F$2:$F$251,A48,'Raw Data'!$K$2:$K$251,$B$3,'Raw Data'!$G$2:$G$251,$B$4,'Raw Data'!$J$2:$J$251,$B$5) -> 89 | D48: =RANK(B48,$B$43:$B$52)+COUNTIF($B$43:B48,B48)-1 -> 7 | F48: 6 | G48: =INDEX($A$43:$A$52,MATCH(F48,$D$43:$D$52,0)) -> Office Chair | H48: =INDEX($B$43:$B$52,MATCH(F48,$D$43:$D$52,0)) -> 10399.48
A49: Laptop | B49: =SUMIFS('Raw Data'!$N$2:$N$251,'Raw Data'!$F$2:$F$251,A49,'Raw Data'!$K$2:$K$251,$B$3,'Raw Data'!$G$2:$G$251,$B$4,'Raw Data'!$J$2:$J$251,$B$5) -> 67499.25 | C49: =SUMIFS('Raw Data'!$H$2:$H$251,'Raw Data'!$F$2:$F$251,A49,'Raw Data'!$K$2:$K$251,$B$3,'Raw Data'!$G$2:$G$251,$B$4,'Raw Data'!$J$2:$J$251,$B$5) -> 75 | D49: =RANK(B49,$B$43:$B$52)+COUNTIF($B$43:B49,B49)-1 -> 1 | F49: 7 | G49: =INDEX($A$43:$A$52,MATCH(F49,$D$43:$D$52,0)) -> Keyboard | H49: =INDEX($B$43:$B$52,MATCH(F49,$D$43:$D$52,0)) -> 8009.11
...

Sheet Insights Report
B1: FINAL REPORT - INSIGHTS & STORYTELLING
B2: Every sentence below is a live formula, so it updates when the data changes.
B4: 1. Headline
B5: ="The business earned "&TEXT(Analysis!B39,"$#,##0")&" from "&TEXT(COUNTA('Raw Data'!$A$2:$A$251),"#,##0")&" orders placed by "&COUNTIF(Analysis!E85:E134,">0")&" customers between "&TEXT(Analysis!B6,"mmm yyyy")&" and "&TEXT(Analysis!B7,"mmm yyyy")&". The average order is worth "&TEXT(Analysis!E180,"$#,##0")&"." -> The business earned $229,192 from 250 orders placed by 50 customers between Apr 2024 and Apr 2025. The average order is worth $917.
B7: 2. Regional sales
B8: =Analysis!B181&" is the strongest region with "&TEXT(MAX(Analysis!D175:D179),"0.0%")&" of total revenue ("&TEXT(MAX(Analysis!C175:C179),"$#,##0")&"). The weakest region is "&Analysis!B182&" with "&TEXT(MIN(Analysis!D175:D179),"0.0%")&" - the best place to look for growth." -> East is the strongest region with 25.9% of total revenue ($59,288). The weakest region is South with 15.9% - the best place to look for growth.
B10: 3. Customers
B11: ="Top customer is "&Analysis!B138&" ("&TEXT(Analysis!E138,"0.0%")&" of revenue). The "&Analysis!B143&" High-Value customers (top "&TEXT(Analysis!B80,"0%")&") bring "&TEXT(Analysis!D143,"0%")&" of all revenue, so protecting them matters most." -> Top customer is Mark Carter (6.8% of revenue). The 10 High-Value customers (top 20%) bring 41% of all revenue, so protecting them matters most.
B13: 4. Loyalty
B14: =TEXT(Analysis!D164,"0%")&" of customers bought more than once. The most loyal buyer is "&Analysis!B162&" with "&Analysis!B163&" orders." -> 94% of customers bought more than once. The most loyal buyer is Mark Carter with 12 orders.
B16: 5. Products
B17: ="The most frequently bought product is "&Analysis!B159&"; the most units sold is "&Analysis!B160&"; the highest revenue comes from "&Analysis!B161&". Volume and value can be different stories." -> The most frequently bought product is Bookshelf; the most units sold is Bookshelf; the highest revenue comes from Laptop. Volume and value can be different stories.
B19: 6. Trend & forecast
B20: =Analysis!H61&". The model explains "&TEXT(Analysis!I58,"0%")&" of month-to-month variation (R-squared) and forecasts about "&TEXT(Analysis!I60,"$#,##0")&" for the next month." -> Revenue is trending UP by about $338 every month. The model explains 8% of month-to-month variation (R-squared) and forecasts about $20,330 for the next month.
B22: 7. What-if
B23: ="With price "&TEXT(Analysis!B40,"+0%;-0%")&", quantity "&TEXT(Analysis!B41,"+0%;-0%")&" and discount "&TEXT(Analysis!B42,"0%")&", revenue would be "&TEXT(Analysis!B43,"$#,##0")&" ("&TEXT(Analysis!B44,"+$#,##0;-$#,##0")&" vs actual). Best case "&TEXT(Analysis!E50,"$#,##0")&", worst case "&TEXT(Analysis!E52,"$#,##0")&"." -> With price +5%, quantity +10% and discount 2%, revenue would be $259,423 (+$30,230 vs actual). Best case $289,928, worst case $206,846.
B25: 8. Recommendations (edit after you read the numbers)
B26: Focus retention offers on High-Value and repeat customers; run a campaign in the weakest region; bundle the most-bought product with high-revenue products to lift average order value.

Sheet Manual Steps
A1: STEP-BY-STEP: features that must be done by hand in Excel
A3: PIVOT TABLES | B3: 1) Click any cell in the Raw Data table. 2) Insert > PivotTable > New Worksheet, name it 'Pivots'. 3) Pivot 1: Rows = Region, Values = Sum of Total_Amount. 4) Pivot 2: Rows = Month End (group by Months and Years), Values = Sum of Total_Amount. 5) Pivot 3: Rows = Category, Values = Sum of Total_Amount. 6) Pivot 4: Rows = Product_Name, Values = Sum of Quantity.
A4: PIVOT CHARTS | B4: Click inside a pivot > PivotTable Analyze > PivotChart. Pivot 1 = Bar (clustered column), Pivot 2 = Line, Pivot 3 = Pie. Cut the charts and paste them on the Dashboard sheet (below the existing charts, or replace them).
A5: SLICERS | B5: Click a pivot > PivotTable Analyze > Insert Slicer > tick Region, Category, Payment_Method, Customer_Segment. Right-click each slicer > Report Connections > tick ALL pivots so one click filters the whole dashboard.
A6: TIMELINE | B6: Click a pivot > PivotTable Analyze > Insert Timeline > Date. Connect it to all pivots with Report Connections. Drag the bar to filter by months.
A7: SCENARIO MANAGER | B7: Data > What-If Analysis > Scenario Manager > Add. Changing cells: Analysis!B40:B42. Best = 10%, 15%, 0% | Base = 5%, 10%, 2% | Worst = 0%, -5%, 5%. Then click Summary > Scenario summary, Result cell = Analysis!B43.
A8: GOAL SEEK | B8: Data > What-If Analysis > Goal Seek. Set cell = Analysis!B43 | To value = the number in B45 | By changing cell = Analysis!B40. Excel finds the price increase needed to reach the target revenue.
A9: REGRESSION (Data Analysis Toolpak) | B9: File > Options > Add-ins > Manage Excel Add-ins > Go > tick Analysis ToolPak. Data > Data Analysis > Regression. Input Y Range = Analysis!D56:D66 | Input X Range = Analysis!A56:A66 | tick Labels off | Output = New Worksheet. Read: R Square (how well the line fits), Significance F (below 0.05 means the trend is real), X Variable 1 coefficient (= slope in I56).
A10: ITERATIVE TIMESTAMP | B10: File > Options > Formulas > tick 'Enable iterative calculation'. Then =IF(B34="","",IF(B35="",NOW(),B35)) in B35 freezes the time when B34 is filled.
A11: FILTER (Excel 365) | B11: In a blank area type the formula shown in Analysis!B17. It spills all matching rows automatically. Change Analysis!B16 to switch region.
